Workbook

Sheet Daily Log
A1: Date | B1: Day | C1: Sprint # | D1: Task # (per sprint) | E1: Task / User Story | F1: Category | G1: Description of Work Done | H1: Hours Spent | I1: Status | J1: Blockers / Notes | K1: Deliverable / Output
A2: 46146 | B2: =IF(A2="","",TEXT(A2,"dddd")) -> Monday | C2: 1 | D2: =IF(C2="","",COUNTIF($C$2:C2,C2)) -> 1 | E2: refactor code and bug fix | F2: Development | G2: Updated frontend UI/UX to show toast events: success toast on successful Apex call, success toast with workflow end status when ticket workflow completes, and error toast using standard error-handling strategy for failures. | H2: 2 | I2: Done | K2: branch : manage_ticket_page ------------------------------------------ commit :[fce793aaffa41e98ce7a31d834f4780ebf7cf585] ------------------------------------------
A3: 46146 | B3: =IF(A3="","",TEXT(A3,"dddd")) -> Monday | C3: 1 | D3: =IF(C3="","",COUNTIF($C$2:C3,C3)) -> 2 | E3: refactor code and bug fix | F3: Development | G3: Implemented conditional CSS styling on ticketBoardColumn (child LWC) based on workflow end status received from manageTicketTracking (parent LWC) after an Apex callout that updates ticket status. Refactored the data contract so the state object passed from parent to child includes both entity fields and calculated fields (e.g. endStatus) instead of passing the flag as a separate property — keeps the API clean and avoids prop drilling. Since LWC doesn't support dynamic className binding on a child component's internal container from the parent (parent only controls the root element's class), applied the styling via a data-end-status HTML attribute on the child's container and targeted it in CSS with the attribute selector .ticket-card[data-end-status="true"]. | H3: 0.5 | I3: Done | K3: notepad_rule_file :how_child_know_style_basedonpatherstate ----------------------------------------- branch : manage_ticket_page ----------------------------------------- commit : [34c1c058530a1749cdc087ce6f35ac8b9b304d88]
A4: 46146 | B4: =IF(A4="","",TEXT(A4,"dddd")) -> Monday | C4: 1 | D4: =IF(C4="","",COUNTIF($C$2:C4,C4)) -> 3 | E4: add Ticket Link To | F4: Development | G4: in the right page requirement 1- add the main action to show the ticket link 2- add usecase documentation for this action 3- add the request api 4- add the dto 5- add the sequence for the backEnd lifeCycle Say who own the pop up describe how the pop up looks like describe the frontEnd flow and component communication describe how the call should be done :(@wire and describe how we should work with @ wire : framework detail) | H4: 2 | I4: Done | J4: blocked until 8 end | K4: branch : manage_ticket_page ------------------------------------------ commit :[ { 7c8f41af75042c1b442a762c4302179f9573c30b, manually} , { 05ba22fdea6c95581a00eb21c2642c604644fc44, P013 } ] with the previous commit also manually created ------------------------------------------
A5: 46147 | B5: Monday | C5: 1 | D5: =IF(C5="","",COUNTIF($C$2:C5,C5)) -> 4 | E5: when a sprint is started I cant clicked it again (BUG) | F5: Development | I5: Not Started | J5: blocked until 8 end
A6: 46147 | B6: Monday | C6: 1 | D6: =IF(C6="","",COUNTIF($C$2:C6,C6)) -> 5 | E6: As a user I want to see the total story point completed , total story point uncompleted and total story points for each sprint | F6: Development | I6: Not Started | J6: blocked until 8 end
A7: 46147 | B7: Monday | C7: 1 | D7: =IF(C7="","",COUNTIF($C$2:C7,C7)) -> 6 | E7: Create a excel file for prompt study | F7: Other | H7: 1.12 | I7: Done | K7: file : prompt_study
A8: 46147 | B8: Monday | C8: 1 | D8: =IF(C8="","",COUNTIF($C$2:C8,C8)) -> 7 | E8: Problem 1 is about consistency — the container and the child live in different places in the DOM(different lwc) but must change shape together, so one of them can't decide independently. Problem 2 is about the second parent breaking the assumption that screen size is what drives everything — it always wants cards, and it needs them smaller, which variant = "row" | "card" alone can't express. | F8: Planning | G8: Solution 1 answers: "who owns the decision?" — the parent owns it once, and both the container class and the child prop react to the same value. Neither the container nor the child makes an independent decision about screen size. Solution 2 answers: "what if the trigger is different per parent?" — by splitting variant into shape and size, each parent only controls what it actually knows about. Parent 1 knows about screen size so it sets shape. Parent 2 knows it lives in a tight column so it sets size = compact. The child just renders whatever combination it receives, without caring where it came from. Found the right prompts for my case | H8: 3 | I8: Done | J8: Cannot mark as completed until see result of #Task 8 | K8: file : lwc_tow_problems.svg --------------------------------------- Found the right Group of prompts [ P003: {branch : manage_ticket_page commit : 4b17418667db0275a3d8a4de22240a6b345d3bcc}, P004:{branch: manage_ticket_page, commit: af86d0c0e08907aae8c1958132891d2cee267357}, P005{branch : manage_ticket_page, commit : d0ca35292af2db81abf475b1ed96fa580dc9f049} ]
A9: 46147 | B9: Monday | C9: 1 | D9: =IF(C9="","",COUNTIF($C$2:C9,C9)) -> 8 | E9: BUG: in Ticket Tracking page when we load the page and a ticket have hit the endStatus of the assigned workflow to it s type : It does not show as that . | F9: Development | H9: 1 | I9: Done | K9: 5/5/2026-task6-G002-[P006-P007-P008] branch : manage-ticket_page commit : 4587551c9913647c93a7a82d5934169d19c2761d
A10: 46147 | B10: Monday | C10: 1 | D10: =IF(C10="","",COUNTIF($C$2:C10,C10)) -> 9 | E10: BUG : assignee field is not showed for ticket tracking | F10: Development | I10: Done
A11: 46148 | B11: Tuesday | C11: 1 | D11: =IF(C11="","",COUNTIF($C$2:C11,C11)) -> 10 | E11: BUG : ticket type value is not showed | F11: Development | G11: Time to found problem : 10 min, Time to solve the problem with test : 10 min, Time commit + push + update prompt text and set the tas done : 10 min | H11: 0.2 | I11: Done | K11: branch : manage_ticket_page commit : ae26070df27f40cbe4d9d46dfa0c085b6099cb9c
A12: 46148 | B12: Wednesday | C12: 1 | D12: =IF(C12="","",COUNTIF($C$2:C12,C12)) -> 11 | E12: ticket link | F12: Development | H12: 2 | I12: Done | K12: branch : manage_ticket_page commit : 7c8f41af75042c1b442a762c4302179f9573c30b
A13: 46148 | B13: Wednesday | C13: 1 | D13: =IF(C13="","",COUNTIF($C$2:C13,C13)) -> 12 | E13: Plan to change end status | F13: Planning | G13: `- update er TASK 13 - update erd TASK 14 - plan for the development change TASK 15 | H13: 0.3 | I13: Blocked | J13: TASK 13 TASK 14
A14: 46148 | B14: Wednesday | C14: 1 | D14: =IF(C14="","",COUNTIF($C$2:C14,C14)) -> 13 | E14: UPDATE ER | F14: Design | G14: A PROJECT SHOULD HAVE A SINGLE START STATUS. A PROJECT SHOULD HAVE A SINGLE END STATUS. | H14: 0.1 | I14: Done | K14: branch : manage_ticket_page commit hash : 501b221833fc2b4d09bc60bf11577d8c8379bb5c commit message : watch blue change in new_er_diagram or Untitled Diagram-Page2.drawio.png
A15: 46148 | B15: Wednesday | C15: 1 | D15: =IF(C15="","",COUNTIF($C$2:C15,C15)) -> 14 | E15: UPDATE ERD | F15: Design | G15: FOLLOWING THE ER RELATIONSHIP: A project has many statuses, but it must also have exactly one Start Status and one End Status. PROBLEM: If we store `startStatusId` and `endStatusId` directly in the `Project` table, this creates double coupling between `Project` and `Status`: * `Project` already owns multiple `Status` records (1-to-many) * Adding `startStatusId` and `endStatusId` creates extra direct references back to `Status` This design can become harder to maintain and unnecessarily increases structural complexity. SOLUTION 1: Normalize using a Many-to-Many (M:N) relationship A separate mapping structure could be created to define special status roles such as Start and End. DRAWBACK: This approach is too complex for a simple requirement where each project only needs: * One fixed Start Status * One fixed End Status SOLUTION 2: Add flags inside `Status` Add: * `isStart` * `isEnd` This keeps the structure simpler, but introduces integrity and security risks because users could: * Modify the flags later * Create multiple Start or End statuses for the same project REQUIRED DATABASE PROTECTION (TRIGGERS): 1. Project Creation Trigger * Automatically create default statuses when a project is created: * `Todo` with `isStart = true` * `Done` with `isEnd = true` 2. Status Update Trigger * Prevent updates to `isStart` and `isEnd` after creation 3. Status Insert Trigger * If a new status has `isStart = true`, verify that no other Start status already exists in that project * If a new status has `isEnd = true`, verify that no other End status already exists in that project FINAL RESULT: This ensures: * Exactly one Start Status per project * Exactly one End Status per project * No duplicate flagged statuses * Strong integrity enforcement * Simpler ER design without unnecessary normalization complexity | H15: 0.3 | I15: Blocked | J15: TASK 15
A16: 46148 | B16: Wednesday | C16: 1 | D16: =IF(C16="","",COUNTIF($C$2:C16,C16)) -> 15 | E16: plan for the development change | F16: Planning | G16: Found the previous code that is affected : - DomainCompleteValidator : isEndStatus - TicketService : changeTicketState - ManageTicketTrackingController - ManageBacklogController - manageTicketTracking.js : _loadData method | H16: 0.4 | I16: Blocked | J16: Task 16 | K16: commit hash : 35b63489ea349ff172c16329adc6603cc1a7256f commit message : 5/7/2026-sprint1-[task15-task16]
A17: 46148 | B17: Wednesday | C17: 1 | D17: =IF(C17="","",COUNTIF($C$2:C17,C17)) -> 16 | F17: Development | G17: P014 - P015 - P016 | H17: 0.3 | I17: Done | K17: commit hash : 35b63489ea349ff172c16329adc6603cc1a7256f commit message : 5/7/2026-sprint1-[task15-task16]
A18: 46148 | B18: Wednesday | C18: 1 | D18: =IF(C18="","",COUNTIF($C$2:C18,C18)) -> 17 | E18: show : - total story point for sprint - total ended story point for sprint | F18: Planning | G18: `- update er - update erd - plan for development | I18: Blocked | J18: task 18 , task 19 , task 20
A19: 46148 | B19: Wednesday | C19: 1 | D19: =IF(C19="","",COUNTIF($C$2:C19,C19)) -> 18 | E19: update er | F19: Design | H19: 0.1 | I19: Done | K19: branch name : manage_ticket_page commit hash : a8193931ef03369bdd50760f6265aa6c78f6ea7e commit message : 5/6/2026-sprint1-Task18
A20: 46148 | B20: Wednesday | C20: 1 | D20: =IF(C20="","",COUNTIF($C$2:C20,C20)) -> 19 | E20: update erd | F20: Development | G20: create new 2 field in sprint object | H20: 0.1 | I20: Done | K20: branch name : manage_ticket_page commit hash : 6890797f7bb9ab5798e19611670a5f55f8072574 commit message : 5/6/2026-sprint1-Task19
A21: 46148 | B21: Wednesday | C21: 1 | D21: =IF(C21="","",COUNTIF($C$2:C21,C21)) -> 20 | E21: plan for development | F21: Planning | G21: For Manage Ticket Tracking Page : - show the total story point - show the ended total story point For Manage Backlog Page : in each sprint container : - show the total story point - show the ended total story point When ticket hit the end status : - ended story point will be increased by the ticket story point if the transaction sucees. | H21: 0.4 | I21: In Progress | J21: Task 21-22
A22: 46148 | B22: Wednesday | C22: 1 | D22: =IF(C22="","",COUNTIF($C$2:C22,C22)) -> 21 | E22: show total story points and ended story points in manageTicketTracking page | F22: Development | H22: 0.2 | I22: Done
A23: 46148 | B23: Wednesday | C23: 1 | D23: =IF(C23="","",COUNTIF($C$2:C23,C23)) -> 22 | E23: show total story points and ended story points in manageBacklog page | F23: Development | H23: 0.1 | I23: Done
A24: 46149 | B24: Thursday | C24: 1 | D24: =IF(C24="","",COUNTIF($C$2:C24,C24)) -> 23 | E24: update ui to match jira | F24: Development | H24: 0.5 | I24: Done
A25: 46149 | B25: =IF(A25="","",TEXT(A25,"dddd")) -> Thursday | C25: 1 | D25: =IF(C25="","",COUNTIF($C$2:C25,C25)) -> 24 | E25: optimise code for maintainability in manageBacklogPage.js | F25: Development | H25: 0.2 | I25: Done
A26: 46149 | B26: Thursday | C26: 1 | D26: =IF(C26="","",COUNTIF($C$2:C26,C26)) -> 25 | E26: when create a new ticket in the sprint container we should update the total story point in it. | F26: Development | I26: Blocked | J26: Task 27
A27: 46149 | B27: =IF(A27="","",TEXT(A27,"dddd")) -> Thursday | C27: 1 | D27: =IF(C27="","",COUNTIF($C$2:C27,C27)) -> 26 | E27: when achieve the done status in the manage ticket tracking page we should update the ended story point so in the same time the total story point will be updated. | F27: Development | I27: Not Started
A28: 46149 | B28: Thursday | C28: 1 | D28: =IF(C28="","",COUNTIF($C$2:C28,C28)) -> 27 | E28: Bug(manageBacklogPage.js): the story point is calculated based on the retrieved paging not the full sprint story points, Bug(manageTicketTracking.js): the story point is calculated on the retrieve ticket. Solution we have already create totalStoryPoint and ended story points in the Sprint table so we should get from it. | F28: Development | G28: what is affected by creating the totalStoryPoint and totalEndedStoryPoint : BackEnd: - select total story point from the sprint not calculate : * update load Ticket Tracking, * update load Sprints. - create ticket >> should affect the total story point. - delete ticket >> should affect the total story point. - update the story point for a ticket should affect the total story point (cannot update the story point for ticket in the end status for the current project). - move ticket to backlog - move ticket to sprint - achieve ticket end status | H28: 0.4 | I28: Blocked | J28: task 28 , task 29, task 30
A29: 46149 | B29: Thursday | C29: 1 | D29: =IF(C29="","",COUNTIF($C$2:C29,C29)) -> 28 | E29: `- select total story point from the sprint not calculate : * update load Ticket Tracking, * update load Sprints. | F29: Development | G29: create and update the correct functions + Test without a prompt | H29: 1 | I29: Done | K29: branch : manage_ticket commit : e5745726798c20d1c7b57a1cc501945528bda07a
A30: 46149 | B30: Thursday | C30: 1 | D30: 29 | E30: `- create ticket >> should affect the total story point. So when user create a ticket the totalStoryPoint should be updated | F30: Development | G30: create and update the correct functions + Test without a prompt , update the front End state : | H30: 1 | I30: Done | K30: branch : commit : d3ff3b37b5a7da4b87f409390e81d24647711433
A31: 46149 | B31: Thursday | C31: 1 | D31: 30 | E31: `- delete ticket and delete tickets>> should affect the total story point. | F31: Development | G31: create and update the correct functions + Test without a prompt : 0.5-> this part manually update the frontEnd state : -> this part prompt | H31: 3 | I31: Done | K31: commit : 242d8fb23d43b385ab646167a1bd352e1f81a7d7 commit message : 5/7/2026-sprint1-Task-30
A32: 46150 | B32: Friday | C32: 1 | D32: 31 | E32: `- update the story point for a ticket should affect the total story point (cannot update the story point for ticket in the end status for the current project). | F32: Development | I32: Not Started
A33: 46150 | B33: Friday | C33: 1 | D33: 32 | E33: `- move ticket to backlog | F33: Development | G33: I do the change manually in frontEnd Then isee the network request and from it I know the controller and method , Then I set the Todo then I give the ai the prompt for backEnd BackEnd : 15 min : AI >> P033. ______________ I am aware on what to change in front End so simply i update the state based on the new response and test i have some problem but i solve in debugging FrontEnd : 10 min : Manually with debugging | H33: 0.3 | I33: Done | J33: Task 34 | K33: branch : manage_ticket_page commit hash :395d5e0ca9b751e8bf99ac66f205ec356cac47b5 commit message : 5/8/2026-sprint1-Task32
A34: 46150 | B34: Friday | C34: 1 | D34: 33 | E34: `- move ticket to sprint | F34: Development | G34: I do the change manually in frontEnd Then isee the network request and from it I know the controller and method , Then I set the Todo then I give the ai the prompt for backEnd BackEnd : 20 min : AI >> P033. 18 min _______________ | H34: 0.3 | I34: Blocked | J34: 34 | K34: branch : manage_ticket_page commit hash : f5dff0b41d8e95f198e6a71a2e5d9e65386c110c commit message : 5/8/2026-sprint1-[Task33-Task34]
A35: 46150 | B35: Friday | C35: 1 | D35: 34 | E35: ` front end BUG : we should return the sprint for the story point update because someone else can use the same app and update another sprint so if we update the frontEnd based on just this ticket change so user will not show another user change. , and this cannot be updated using wire because we have paging | F35: Development | G35: `- update createTicket Response in backEnd - update the handler in js with enrich method I do prompt Task34 but it was not enough | H35: 1 | I35: Done | K35: branch : manage_ticket_page commit hash : f5dff0b41d8e95f198e6a71a2e5d9e65386c110c commit message : 5/8/2026-sprint1-[Task33-Task34]
A36: 46150 | B36: Friday | C36: 1 | D36: 35 | E36: `-achieve Ticket End status in Ticket Trackign Page `-achieve Ticket End status in Manage Backlog Page | F36: Development | G36: `- In Manage Ticket Tracking : do change and see the request to know the controller and method in apex . `- in apex update the logic and the return response . `- in lwc update the state based on the return object | I36: Blocked | J36: Task 36 , 37
A37: 46150 | B37: Friday | C37: 1 | D37: 36 | E37: `-achieve Ticket End status in Ticket Trackign Page and Manage Backlog: BACKEND | F37: Development | G37: Update BackEnd Then create a anonymous apex call to check if I have the expected return response | H37: 0.3 | I37: Done
A38: 46150 | B38: Friday | C38: 1 | D38: 37 | E38: `-achieve Ticket End status in Ticket Trackign Page and Manage Backlog: FRONTEND | F38: Development | G38: Update FrontEnd based on the new return response | H38: 0.3 | I38: Done
B39: Friday | C39: 1 | D39: 38
B40: =IF(A40="","",TEXT(A40,"dddd")) | D40: =IF(C40="","",COUNTIF($C$2:C40,C40))
...

Sheet Sprint Plan
A1: Sprint # | B1: Goal / Theme | C1: Start Date | D1: End Date | E1: Duration (days) | F1: Status
A2: 1 | B2: Sprint 1 goal — describe here | C2: 46146 | D2: 46159 | E2: =D2-C2+1 -> 14 | F2: Not Started
A3: 2 | B3: Sprint 2 goal — describe here | C3: 46160 | D3: 46173 | E3: =D3-C3+1 -> 14 | F3: Not Started
A4: 3 | B4: Sprint 3 goal — describe here | C4: 46174 | D4: 46187 | E4: =D4-C4+1 -> 14 | F4: Not Started
A5: 4 | B5: Sprint 4 goal — describe here | C5: 46188 | D5: 46201 | E5: =D5-C5+1 -> 14 | F5: Not Started
A6: 5 | B6: Sprint 5 goal — describe here | C6: 46202 | D6: 46215 | E6: =D6-C6+1 -> 14 | F6: Not Started
A7: 6 | B7: Sprint 6 goal — describe here | C7: 46216 | D7: 46229 | E7: =D7-C7+1 -> 14 | F7: Not Started

Sheet Summary
A1: Project Summary
A3: Total hours logged | B3: =SUM('Daily Log'!H2:H248) -> 22.42
A4: Total tasks logged | B4: =COUNTA('Daily Log'!E2:E248) -> 38
A5: Distinct days worked | B5: =SUMPRODUCT(('Daily Log'!A2:A248<>"")/COUNTIF('Daily Log'!A2:A248,'Daily Log'!A2:A248&"")) -> 5
A6: Avg tasks per day | B6: =IFERROR(B4/B5,0) -> 7.6
A7: Avg hours per day | B7: =IFERROR(B3/B5,0) -> 4.484
A8: Tasks Done | B8: =COUNTIF('Daily Log'!I2:I248,"Done") -> 25
A9: Tasks In Progress | B9: =COUNTIF('Daily Log'!I2:I248,"In Progress") -> 1
A10: Tasks Blocked | B10: =COUNTIF('Daily Log'!I2:I248,"Blocked") -> 9
A11: Completion % | B11: =IFERROR(B8/B4,0) -> 0.65789474
A13: Hours by Category | D13: Hours by Sprint
A14: Planning | B14: =SUMIF('Daily Log'!F2:F248,A14,'Daily Log'!H2:H248) -> 4.1 | D14: Sprint 1 | E14: =SUMIF('Daily Log'!C2:C248,1,'Daily Log'!H2:H248) -> 22.42
A15: Design | B15: =SUMIF('Daily Log'!F2:F248,A15,'Daily Log'!H2:H248) -> 0.5 | D15: Sprint 2 | E15: =SUMIF('Daily Log'!C2:C248,2,'Daily Log'!H2:H248) -> 0
A16: Development | B16: =SUMIF('Daily Log'!F2:F248,A16,'Daily Log'!H2:H248) -> 16.7 | D16: Sprint 3 | E16: =SUMIF('Daily Log'!C2:C248,3,'Daily Log'!H2:H248) -> 0
A17: Testing | B17: =SUMIF('Daily Log'!F2:F248,A17,'Daily Log'!H2:H248) -> 0 | D17: Sprint 4 | E17: =SUMIF('Daily Log'!C2:C248,4,'Daily Log'!H2:H248) -> 0
A18: Documentation | B18: =SUMIF('Daily Log'!F2:F248,A18,'Daily Log'!H2:H248) -> 0 | D18: Sprint 5 | E18: =SUMIF('Daily Log'!C2:C248,5,'Daily Log'!H2:H248) -> 0
A19: Meeting | B19: =SUMIF('Daily Log'!F2:F248,A19,'Daily Log'!H2:H248) -> 0 | D19: Sprint 6 | E19: =SUMIF('Daily Log'!C2:C248,6,'Daily Log'!H2:H248) -> 0
A20: Research | B20: =SUMIF('Daily Log'!F2:F248,A20,'Daily Log'!H2:H248) -> 0
A21: Setup | B21: =SUMIF('Daily Log'!F2:F248,A21,'Daily Log'!H2:H248) -> 0
A22: Deployment | B22: =SUMIF('Daily Log'!F2:F248,A22,'Daily Log'!H2:H248) -> 0
A23: Other | B23: =SUMIF('Daily Log'!F2:F248,A23,'Daily Log'!H2:H248) -> 1.12
